Workbook

Sheet Models
E3: Sales | G3: Purchase | I3: HR | K3: DQ
E8: currency
E10: date dim

Sheet Purchase
C3: OAON enters in contract with different vendors | H3: Vendors are different businesses who supply goods.
B5: 1 | C5: Each contract has a unique contract id | H5: PurchContracts
A7: FirstParty | B7: 2 | C7: OaOn has registered subsidiaries in different countries | H7: OaonParties | I7: OaOnPartyAddress
A9: SecondParty | B9: 3 | C9: Vendors supply goods | H9: VendTable
B11: 4 | C11: After contract is signed, PO is raised | H11: PurchaseOrder
B13: 5 | C13: Items are shipped from vendors to Oaon subsidiaries | H13: PurchItem
B15: 6 | C15: Categories | H15: PurchCategory

Sheet OaOnParties
A1: PartyId | B1: OaOnPartyName | C1: PartyAddressCode | D1: EstablishedDate | E1: PartyEmailId | F1: PartyContactNumber | G1: RecordId | H1: TaxId

Sheet OaOnPartyAddress
A1: PartyNumber | B1: Address | C1: City | D1: State | E1: Country | F1: ZipCode | G1: Region | H1: ValidFrom | I1: ValidTo | J1: RecordId

Sheet VendTable
A1: VendId | B1: VendorName | C1: LastProcessedChange_DateTime | D1: DataLakeModified_DateTime | E1: Address | F1: City | G1: State | H1: Country | I1: ZipCode | J1: Region | K1: ValidFrom | L1: ValidTo | M1: Active | N1: RecordId | O1: TaxId | P1: CurrencyCode
A2: 700001 | B2: Xgen-Ecommerce | D2: 45293 | H2: SaudiArabia | J2: MiddleEast | K2: 39448 | L2: 46002 | M2: 1 | N2: 36429234 | O2: XGE24CE | P2: SAR
A3: 700002 | B3: Destination-Ecommerce | D3: 45293 | H3: UAE | J3: MiddleEast | K3: 39449 | L3: 46009 | M3: 1 | N3: 36429234 | O3: DES89CE | P3: AED | S3: Future | T3: Shipping | W3: United States | Y3: US | Z3: United States | AA3: USD
A4: 700003 | B4: UltraSpeed-WholeSale | D4: 45293 | H4: UAE | J4: MiddleEast | K4: 39455 | L4: 46018 | M4: 1 | N4: 36429234 | O4: ULT42LE | P4: AED | S4: NewAge | T4: Products | W4: Europe | Y4: UK | Z4: Europe | AA4: GBP
A5: 700004 | B5: Buzzing-Ecommerce | D5: 45293 | H5: Qatar | J5: MiddleEast | K5: 39464 | L5: 46020 | M5: 1 | N5: 36429234 | O5: BUZ96CE | P5: QAR | S5: Xgen | T5: WholeSale | W5: MiddleEast | Y5: UAE | Z5: MiddleEast | AA5: AED
A6: 700005 | B6: USP-Shippers | D6: 45293 | H6: Kuwait | J6: MiddleEast | K6: 39465 | L6: 46024 | M6: 1 | N6: 36429234 | O6: USP59RS | P6: KWD | S6: TechBiz | T6: Ecommerce | W6: Asia | Y6: SaudiArabia | Z6: MiddleEast | AA6: SAR
A7: 700006 | B7: FMCG-WholeSale | D7: 45293 | H7: UAE | J7: MiddleEast | K7: 39475 | L7: 46025 | M7: 1 | N7: 36429234 | O7: FMC12LE | P7: AED | S7: FMCG | T7: Supplier | W7: Australia | Y7: Qatar | Z7: MiddleEast | AA7: QAR
A8: 700007 | B8: Stocker-WholeSale | D8: 45293 | H8: UK | J8: Europe | K8: 39482 | L8: 46030 | M8: 1 | N8: 36429234 | O8: STO29LE | P8: GBP | S8: AZM | T8: Movers | Y8: Kuwait | Z8: MiddleEast | AA8: KWD
A9: 700008 | B9: TechBiz-Shippers | D9: 45293 | H9: Qatar | J9: MiddleEast | K9: 39484 | L9: 46034 | M9: 1 | N9: 36429234 | O9: TEC18RS | P9: QAR | S9: Buzzing | T9: Shippers | Y9: Egypt | Z9: MiddleEast | AA9: EGP
A10: 700009 | B10: Rapid-WholeSale | D10: 45293 | H10: India | J10: Asia | K10: 39488 | L10: 46039 | M10: 1 | N10: 36429234 | O10: RAP82LE | P10: INR | S10: Destination | Y10: Turkiye | Z10: MiddleEast | AA10: TRP
A11: 700010 | B11: Stocker-Products | D11: 45293 | H11: SaudiArabia | J11: MiddleEast | K11: 39491 | L11: 46040 | M11: 1 | N11: 36429234 | O11: STO92TS | P11: SAR | S11: Stocker | Y11: India | Z11: Asia | AA11: INR
A12: 700011 | B12: Rapid-Movers | D12: 45293 | H12: US | J12: United States | K12: 39496 | L12: 46046 | M12: 1 | N12: 36429234 | O12: RAP26RS | P12: USD | S12: Innovative | Y12: Pakistan | Z12: Asia | AA12: PKR
A13: 700012 | B13: AZM-Shipping | D13: 45293 | H13: UAE | J13: MiddleEast | K13: 39503 | L13: 46047 | M13: 1 | N13: 36429234 | O13: AZM11NG | P13: AED | S13: ShopAtUs | Y13: Australia | Z13: Australia | AA13: AUD
A14: 700013 | B14: Innovative-Movers | D14: 45293 | H14: Pakistan | J14: Asia | K14: 39506 | L14: 46050 | M14: 1 | N14: 36429234 | O14: INN95RS | P14: PKR | S14: Etail
A15: 700014 | B15: Etail-Shippers | D15: 45293 | H15: US | J15: United States | K15: 39510 | L15: 46051 | M15: 1 | N15: 36429234 | O15: ETA12RS | P15: USD | S15: FastDelivery
A16: 700015 | B16: AZM-Supplier | D16: 45293 | H16: Turkiye | J16: MiddleEast | K16: 39512 | L16: 46056 | M16: 1 | N16: 36429234 | O16: AZM21ER | P16: TRP | S16: Rapid
A17: 700016 | B17: Buzzing-Supplier | D17: 45293 | H17: Pakistan | J17: Asia | K17: 39519 | L17: 46061 | M17: 1 | N17: 36429234 | O17: BUZ38ER | P17: PKR | S17: UltraSpeed
A18: 700017 | B18: FastDelivery-Products | D18: 45293 | H18: UK | J18: Europe | K18: 39527 | L18: 46065 | M18: 1 | N18: 36429234 | O18: FAS59TS | P18: GBP | S18: USP
A19: 700018 | B19: UltraSpeed-Supplier | D19: 45293 | H19: Turkiye | J19: MiddleEast | K19: 39532 | L19: 46074 | M19: 1 | N19: 36429234 | O19: ULT27ER | P19: TRP
A20: 700019 | B20: Future-Shipping | D20: 45293 | H20: India | J20: Asia | K20: 39537 | L20: 46083 | M20: 1 | N20: 36429234 | O20: FUT61NG | P20: INR
A21: 700020 | B21: USP-WholeSale | D21: 45293 | H21: US | J21: United States | K21: 39547 | L21: 46088 | M21: 1 | N21: 36429234 | O21: USP55LE | P21: USD
A22: 700021 | B22: Etail-Movers | D22: 45293 | H22: Qatar | J22: MiddleEast | K22: 39553 | L22: 46092 | M22: 1 | N22: 36429234 | O22: ETA77RS | P22: QAR
A23: 700022 | B23: USP-Products | D23: 45293 | H23: Pakistan | J23: Asia | K23: 39554 | L23: 46100 | M23: 1 | N23: 36429234 | O23: USP32TS | P23: PKR
A24: 700023 | B24: TechBiz-Ecommerce | D24: 45293 | H24: Pakistan | J24: Asia | K24: 39559 | L24: 46105 | M24: 1 | N24: 36429234 | O24: TEC45CE | P24: PKR
A25: 700001 | B25: Future-Supplier | D25: 45293 | H25: Kuwait | J25: MiddleEast | K25: 39566 | L25: 46110 | M25: 1 | N25: 36429234 | O25: FUT38ER | P25: KWD
A26: 700002 | B26: ShopAtUs-Ecommerce | D26: 45293 | H26: SaudiArabia | J26: MiddleEast | K26: 39568 | L26: 46118 | M26: 1 | N26: 36429234 | O26: SHO49CE | P26: SAR
A27: 700003 | B27: NewAge-Shipping | D27: 45293 | H27: SaudiArabia | J27: MiddleEast | K27: 39571 | L27: 46126 | M27: 1 | N27: 36429234 | O27: NEW41NG | P27: SAR
A28: 700004 | B28: Etail-Shipping | D28: 45293 | H28: Turkiye | J28: MiddleEast | K28: 39573 | L28: 46131 | M28: 1 | N28: 36429234 | O28: ETA68NG | P28: TRP
A29: 700005 | B29: AZM-Ecommerce | D29: 45293 | H29: US | J29: United States | K29: 39574 | L29: 46141 | M29: 1 | N29: 36429234 | O29: AZM77CE | P29: USD
A30: 700006 | B30: Buzzing-WholeSale | D30: 45293 | H30: Pakistan | J30: Asia | K30: 39580 | L30: 46143 | M30: 1 | N30: 36429234 | O30: BUZ14LE | P30: PKR
... A109: 700016 | B109: Stocker-Movers | D109: 45293 | H109: SaudiArabia | J109: MiddleEast | K109: 40058 | L109: 46558 | M109: 1 | N109: 36429234 | O109: STO66RS | P109: SAR

Sheet Sheet8

Sheet PurchContracts
A1: OaOnContractId | B1: LastProcessedChange_DateTime | C1: DataLakeModified_DateTime | D1: FirstParty | E1: SecondParty | F1: ValidFrom | G1: ValidTo | H1: IsActive | I1: RecordId
A2: 97400000001 | C2: 45293 | D2: 10001 | E2: 700001 | F2: 44927 | G2: 46022 | H2: 1 | I2: 65417281
A3: 97400000002 | C3: 45293 | D3: 10002 | E3: 700002 | F3: 44928 | G3: 46023 | H3: 1 | I3: 65417282
A4: 97400000003 | C4: 45293 | D4: 10003 | E4: 700003 | F4: 44929 | G4: 46024 | H4: 1 | I4: 65417283
A5: 97400000004 | C5: 45293 | D5: 10004 | E5: 700004 | F5: 44930 | G5: 46025 | H5: 1 | I5: 65417284
A6: 97400000005 | C6: 45293 | D6: 10005 | E6: 700005 | F6: 44931 | G6: 46026 | H6: 1 | I6: 65417285
A7: 97400000006 | C7: 45293 | D7: 10006 | E7: 700006 | F7: 44932 | G7: 46027 | H7: 1 | I7: 65417286
A8: 97400000007 | C8: 45293 | D8: 10007 | E8: 700007 | F8: 44933 | G8: 46028 | H8: 1 | I8: 65417287
A9: 97400000008 | C9: 45293 | D9: 10008 | E9: 700008 | F9: 44934 | G9: 46029 | H9: 1 | I9: 65417288
A10: 97400000009 | C10: 45293 | D10: 10009 | E10: 700009 | F10: 44935 | G10: 46030 | H10: 1 | I10: 65417289
A11: 97400000010 | C11: 45293 | D11: 10010 | E11: 700010 | F11: 44936 | G11: 46031 | H11: 1 | I11: 65417290
A12: 97400000011 | C12: 45293 | D12: 10011 | E12: 700011 | F12: 44937 | G12: 46032 | H12: 1 | I12: 65417291
A13: 97400000012 | C13: 45293 | D13: 10012 | E13: 700012 | F13: 44938 | G13: 46033 | H13: 1 | I13: 65417292
... A24: 97400000023 | C24: 45293 | D24: 10022 | E24: 700023 | F24: 44949 | G24: 46044 | H24: 1 | I24: 65417303

Sheet PurchaseOrder
A1: PoNumber | B1: LineItem | C1: VendId | D1: LastProcessedChange_DateTime | E1: DataLakeModified_DateTime | F1: Qty | G1: PurchasePrice | H1: TotalOrder | I1: ExchangeRate | J1: costcenter | K1: Itemkey | L1: currencycode | M1: OrderDate | N1: ShipDate | O1: DeliveredDate | P1: TrackingNumber | Q1: batchid | R1: CreatedBy | S1: RecordId | T1: CategoryId
A2: 952000001 | B2: 1 | C2: =IF(A2=A1,PurchaseOrder!C1,INDEX(VendTable!$A$2:$A$109,RANDBETWEEN(1,23))) -> 700023 | E2: 2024-01-02T14:16:06.9086921Z | F2: 15543 | G2: 9013.7959 | H2: 1.4010143e+08 | I2: 1.4881644 | J2: 76860 | K2: 76891213535 | L2: US | M2: 44601.595 | N2: 44602.189 | O2: 44608.784 | P2: 10397261234 | Q2: 981856 | S2: 25612344 | T2: 500 | U2: 0.59452441 | W2: 76852 | Z2: 76852
A3: 952000001 | B3: 2 | C3: =IF(A3=A2,PurchaseOrder!C2,INDEX(VendTable!$A$2:$A$109,RANDBETWEEN(1,23))) -> 700023 | E3: 2024-01-02T14:16:06.9086921Z | F3: 28211 | G3: 5278.0982 | H3: 1.4890043e+08 | I3: 1.8813002 | J3: 76861 | K3: 76891213636 | L3: US | M3: 44933.595 | N3: 44935.189 | O3: 44942.784 | P3: 10397261234 | Q3: 981946 | S3: 25612434 | T3: 1000 | W3: 76853 | Z3: 76853
A4: 952000001 | B4: 3 | C4: =IF(A4=A3,PurchaseOrder!C3,INDEX(VendTable!$A$2:$A$109,RANDBETWEEN(1,23))) -> 700023 | E4: 2024-01-02T14:16:06.9086921Z | F4: 6594 | G4: 7226.5803 | H4: 47652070 | I4: 1.6100954 | J4: 76861 | K4: 76891213465 | L4: US | M4: 45524.595 | N4: 45525.189 | O4: 45527.784 | P4: 10397261234 | Q4: 981991 | S4: 25612479 | T4: 500 | W4: 76854 | Z4: 76854
A5: 952000002 | B5: 1 | C5: =IF(A5=A4,PurchaseOrder!C4,INDEX(VendTable!$A$2:$A$109,RANDBETWEEN(1,23))) -> 700004 | E5: 2024-01-02T14:16:06.9086921Z | F5: 27796 | G5: 6047.5037 | H5: 1.6809641e+08 | I5: 1.1377751 | J5: 76854 | K5: 76891213212 | L5: US | M5: 45282.595 | N5: 45283.189 | O5: 45293.784 | P5: 10397261234 | Q5: 981890 | S5: 25612378 | T5: 900 | W5: 76855 | Z5: 76855
A6: 952000003 | B6: 1 | C6: =IF(A6=A5,PurchaseOrder!C5,INDEX(VendTable!$A$2:$A$109,RANDBETWEEN(1,23))) -> 700007 | E6: 2024-01-02T14:16:06.9086921Z | F6: 22504 | G6: 7871.7995 | H6: 1.7714698e+08 | I6: 1.9402531 | J6: 76853 | K6: 76891213318 | L6: US | M6: 44715.595 | N6: 44719.189 | O6: 44727.784 | P6: 10397261234 | Q6: 982001 | S6: 25612489 | T6: 900 | W6: 76856 | Z6: 76856
A7: 952000004 | B7: 1 | C7: =IF(A7=A6,PurchaseOrder!C6,INDEX(VendTable!$A$2:$A$109,RANDBETWEEN(1,23))) -> 700006 | E7: 2024-01-02T14:16:06.9086921Z | F7: 44236 | G7: 434.51764 | H7: 19221322 | I7: 1.6510293 | J7: 76862 | K7: 76891213154 | L7: US | M7: 44983.595 | N7: 44986.189 | O7: 44986.784 | P7: 10397261234 | Q7: 982010 | S7: 25612498 | T7: 900 | W7: 76857 | Z7: 76857
A8: 952000005 | B8: 1 | C8: =IF(A8=A7,PurchaseOrder!C7,INDEX(VendTable!$A$2:$A$109,RANDBETWEEN(1,23))) -> 700019 | E8: 2024-01-02T14:16:06.9086921Z | F8: 41200 | G8: 7671.9345 | H8: 3.160837e+08 | I8: 1.8501127 | J8: 76861 | K8: 76891213531 | L8: US | M8: 45193.595 | N8: 45195.189 | O8: 45205.784 | P8: 10397261234 | Q8: 981903 | S8: 25612391 | T8: 400 | W8: 76858 | Z8: 76858
A9: 952000005 | B9: 2 | C9: =IF(A9=A8,PurchaseOrder!C8,INDEX(VendTable!$A$2:$A$109,RANDBETWEEN(1,23))) -> 700019 | E9: 2024-01-02T14:16:06.9086921Z | F9: 27335 | G9: 456.46039 | H9: 12477345 | I9: 1.2223787 | J9: 76860 | K9: 76891213463 | L9: US | M9: 44916.595 | N9: 44920.189 | O9: 44927.784 | P9: 10397261234 | Q9: 981923 | S9: 25612411 | T9: 1000 | W9: 76859 | Z9: 76859
A10: 952000006 | B10: 1 | C10: =IF(A10=A9,PurchaseOrder!C9,INDEX(VendTable!$A$2:$A$109,RANDBETWEEN(1,23))) -> 700012 | E10: 2024-01-02T14:16:06.9086921Z | F10: 6500 | G10: 5988.5573 | H10: 38925622 | I10: 1.2875963 | J10: 76866 | K10: 76891213364 | L10: US | M10: 44860.595 | N10: 44863.189 | O10: 44863.784 | P10: 10397261234 | Q10: 981885 | S10: 25612373 | T10: 100 | W10: 76860 | Z10: 76860
A11: 952000006 | B11: 2 | C11: =IF(A11=A10,PurchaseOrder!C10,INDEX(VendTable!$A$2:$A$109,RANDBETWEEN(1,23))) -> 700012 | E11: 2024-01-02T14:16:06.9086921Z | F11: 39988 | G11: 7141.7755 | H11: 2.8558532e+08 | I11: 1.6454282 | J11: 76864 | K11: 76891213207 | L11: US | M11: 45302.595 | N11: 45304.189 | O11: 45313.784 | P11: 10397261234 | Q11: 981937 | S11: 25612425 | T11: 1000 | W11: 76861 | Z11: 76861
A12: 952000006 | B12: 3 | C12: =IF(A12=A11,PurchaseOrder!C11,INDEX(VendTable!$A$2:$A$109,RANDBETWEEN(1,23))) -> 700012 | E12: 2024-01-02T14:16:06.9086921Z | F12: 6090 | G12: 9901.8673 | H12: 60302372 | I12: 1.2702625 | J12: 76870 | K12: 76891213372 | L12: US | M12: 44900.595 | N12: 44903.189 | O12: 44906.784 | P12: 10397261234 | Q12: 981947 | S12: 25612435 | T12: 500 | W12: 76862 | Z12: 76862
A13: 952000006 | B13: 4 | C13: =IF(A13=A12,PurchaseOrder!C12,INDEX(VendTable!$A$2:$A$109,RANDBETWEEN(1,23))) -> 700012 | E13: 2024-01-02T14:16:06.9086921Z | F13: 43751 | G13: 8471.4389 | H13: 3.7063393e+08 | I13: 1.1615616 | J13: 76865 | K13: 76891213508 | L13: US | M13: 44643.595 | N13: 44646.189 | O13: 44655.784 | P13: 10397261234 | Q13: 981951 | S13: 25612439 | T13: 1000 | W13: 76863 | Z13: 76863
A14: 952000006 | B14: 5 | C14: =IF(A14=A13,PurchaseOrder!C13,INDEX(VendTable!$A$2:$A$109,RANDBETWEEN(1,23))) -> 700012 | E14: 2024-01-02T14:16:06.9086921Z | F14: 42667 | G14: 1104.5531 | H14: 47127966 | I14: 1.7833928 | J14: 76868 | K14: 76891213481 | L14: US | M14: 45037.595 | N14: 45041.189 | O14: 45049.784 | P14: 10397261234 | Q14: 982000 | S14: 25612488 | T14: 1000 | W14: 76864 | Z14: 76864
... A24: 952000014 | B24: 4 | C24: =IF(A24=A23,PurchaseOrder!C23,INDEX(VendTable!$A$2:$A$109,RANDBETWEEN(1,23))) -> 700021 | E24: 2024-01-02T14:16:06.9086921Z | F24: 12901 | G24: 3606.1603 | H24: 46523074 | I24: 1.3257147 | J24: 76862 | K24: 76891213518 | L24: US | M24: 45588.595 | N24: 45589.189 | O24: 45599.784 | P24: 10397261234 | Q24: 982025 | S24: 25612513 | T24: 300 | W24: 76874 | Z24: 76874
A25: 952000014 | B25: 5 | C25: =IF(A25=A24,PurchaseOrder!C24,INDEX(VendTable!$A$2:$A$109,RANDBETWEEN(1,23))) -> 700021 | E25: 2024-01-02T14:16:06.9086921Z | F25: 31557 | G25: 9218.6561 | H25: 2.9091313e+08 | I25: 1.7027658 | J25: 76860 | K25: 76891213157 | L25: US | M25: 45390.595 | N25: 45392.189 | O25: 45394.784 | P25: 10397261234 | Q25: 982026 | S25: 25612514 | T25: 400
A26: 952000016 | B26: 1 | C26: =IF(A26=A25,PurchaseOrder!C25,INDEX(VendTable!$A$2:$A$109,RANDBETWEEN(1,23))) -> 700009 | E26: 2024-01-02T14:16:06.9086921Z | F26: 45398 | G26: 8298.2466 | H26: 3.767238e+08 | I26: 1.2596188 | J26: 76852 | K26: 76891213515 | L26: US | M26: 44750.595 | N26: 44751.189 | O26: 44760.784 | P26: 10397261234 | Q26: 981988 | S26: 25612476 | T26: 600
A27: 952000016 | B27: 2 | C27: =IF(A27=A26,PurchaseOrder!C26,INDEX(VendTable!$A$2:$A$109,RANDBETWEEN(1,23))) -> 700009 | E27: 2024-01-02T14:16:06.9086921Z | F27: 35291 | G27: 722.47856 | H27: 25496991 | I27: 1.0348933 | J27: 76860 | K27: 76891213241 | L27: US | M27: 44693.595 | N27: 44694.189 | O27: 44694.784 | P27: 10397261234 | Q27: 981997 | S27: 25612485 | T27: 700
A28: 952000017 | B28: 1 | C28: =IF(A28=A27,PurchaseOrder!C27,INDEX(VendTable!$A$2:$A$109,RANDBETWEEN(1,23))) -> 700015 | E28: 2024-01-02T14:16:06.9086921Z | F28: 16631 | G28: 8262.4795 | H28: 1.374133e+08 | I28: 1.0519482 | J28: 76871 | K28: 76891213352 | L28: US | M28: 44659.595 | N28: 44663.189 | O28: 44664.784 | P28: 10397261234 | Q28: 981892 | S28: 25612380 | T28: 500
A29: 952000017 | B29: 2 | C29: =IF(A29=A28,PurchaseOrder!C28,INDEX(VendTable!$A$2:$A$109,RANDBETWEEN(1,23))) -> 700015 | E29: 2024-01-02T14:16:06.9086921Z | F29: 11319 | G29: 4691.9138 | H29: 53107772 | I29: 1.4568726 | J29: 76863 | K29: 76891213324 | L29: US | M29: 44668.595 | N29: 44670.189 | O29: 44676.784 | P29: 10397261234 | Q29: 981959 | S29: 25612447 | T29: 100
A30: 952000019 | B30: 1 | C30: =IF(A30=A29,PurchaseOrder!C29,INDEX(VendTable!$A$2:$A$109,RANDBETWEEN(1,23))) -> 700011 | E30: 2024-01-02T14:16:06.9086921Z | F30: 42604 | G30: 6289.9679 | H30: 2.6797779e+08 | I30: 1.0675251 | J30: 76855 | K30: 76891213464 | L30: US | M30: 44841.595 | N30: 44844.189 | O30: 44852.784 | P30: 10397261215 | Q30: 981835 | S30: 25612323 | T30: 200
A31: 952000020 | B31: 1 | C31: =IF(A31=A30,PurchaseOrder!C30,INDEX(VendTable!$A$2:$A$109,RANDBETWEEN(1,23))) -> 700014 | E31: 2024-01-02T14:16:06.9086921Z | F31: 5485 | G31: 5297.7343 | H31: 29058073 | I31: 1.8963767 | J31: 76867 | K31: 76891213450 | L31: US | M31: 45301.595 | N31: 45302.189 | O31: 45308.784 | P31: 10397261234 | Q31: 981927 | S31: 25612415 | T31: 800
A32: 952000020 | B32: 2 | C32: =IF(A32=A31,PurchaseOrder!C31,INDEX(VendTable!$A$2:$A$109,RANDBETWEEN(1,23))) -> 700014 | E32: 2024-01-02T14:16:06.9086921Z | F32: 19524 | G32: 8918.4092 | H32: 1.7412302e+08 | I32: 1.3290569 | J32: 76865 | K32: 76891213415 | L32: US | M32: 45255.595 | N32: 45258.189 | O32: 45263.784 | P32: 10397261234 | Q32: 982013 | S32: 25612501 | T32: 700
A33: 952000021 | B33: 1 | C33: =IF(A33=A32,PurchaseOrder!C32,INDEX(VendTable!$A$2:$A$109,RANDBETWEEN(1,23))) -> 700017 | E33: 2024-01-02T14:16:06.9086921Z | F33: 40304 | G33: 1470.2265 | H33: 59256008 | I33: 1.7222778 | J33: 76866 | K33: 76891213194 | L33: US | M33: 44785.595 | N33: 44789.189 | O33: 44793.784 | P33: 10397261234 | Q33: 981887 | S33: 25612375 | T33: 400
A34: 952000021 | B34: 2 | C34: =IF(A34=A33,PurchaseOrder!C33,INDEX(VendTable!$A$2:$A$109,RANDBETWEEN(1,23))) -> 700017 | E34: 2024-01-02T14:16:06.9086921Z | F34: 24533 | G34: 5173.8412 | H34: 1.2692985e+08 | I34: 1.6626016 | J34: 76855 | K34: 76891213487 | L34: US | M34: 44653.595 | N34: 44654.189 | O34: 44656.784 | P34: 10397261234 | Q34: 981931 | S34: 25612419 | T34: 1000
A35: 952000023 | B35: 1 | C35: =IF(A35=A34,PurchaseOrder!C34,INDEX(VendTable!$A$2:$A$109,RANDBETWEEN(1,23))) -> 700015 | E35: 2024-01-02T14:16:06.9086921Z | F35: 16463 | G35: 7427.1598 | H35: 1.2227333e+08 | I35: 1.9967414 | J35: 76856 | K35: 76891213219 | L35: US | M35: 45370.595 | N35: 45374.189 | O35: 45375.784 | P35: 10397261234 | Q35: 981868 | S35: 25612356 | T35: 400
A36: 952000023 | B36: 2 | C36: =IF(A36=A35,PurchaseOrder!C35,INDEX(VendTable!$A$2:$A$109,RANDBETWEEN(1,23))) -> 700015 | E36: 2024-01-02T14:16:06.9086921Z | F36: 22698 | G36: 1875.5988 | H36: 42572341 | I36: 1.6267861 | J36: 76862 | K36: 76891213612 | L36: US | M36: 45340.595 | N36: 45344.189 | O36: 45354.784 | P36: 10397261234 | Q36: 981902 | S36: 25612390 | T36: 100
... A125: 952000082 | B125: 3 | C125: =IF(A125=A124,PurchaseOrder!C124,INDEX(VendTable!$A$2:$A$109,RANDBETWEEN(1,23))) -> 700007 | E125: 2024-01-02T14:16:06.9086921Z | F125: 7537 | G125: 2139.6017 | H125: 16126178 | I125: 1.4113029 | J125: 76870 | K125: 76891213236 | L125: US | M125: 45409.595 | N125: 45412.189 | O125: 45417.784 | P125: 10397261234 | Q125: 981970 | S125: 25612458 | T125: 900
A126: 952000083 | B126: 1 | C126: =IF(A126=A125,PurchaseOrder!C125,INDEX(VendTable!$A$2:$A$109,RANDBETWEEN(1,23))) -> 700018 | E126: 2024-01-02T14:16:06.9086921Z | F126: =RANDBETWEEN(5000,50000) -> 48179 | G126: =VLOOKUP(K126,PurchItem!$A$2:$H$508,8,0) -> 7411.6309 | H126: =F126*G126 -> 3.5708496e+08 | I126: =1+RAND() -> 1.6536154 | J126: =INDEX($W$2:$W$24,RANDBETWEEN(1,20)) -> 76867 | K126: =INDEX(PurchItem!$A$2:$A$508,RANDBETWEEN(1,500)) -> 76891213350 | L126: US | M126: =RANDBETWEEN(DATE(2022,1,1),TODAY()-30)+$U$2 -> 45256.595 | N126: =M126+RANDBETWEEN(0,3)+$U$2 -> 45259.189 | O126: =N126+RANDBETWEEN(0,10)+$U$2 -> 45264.784 | P126: 10397261213 | Q126: 981833 | S126: 25612321 | T126: 700
A127: 952000083 | B127: 2 | C127: =IF(A127=A126,PurchaseOrder!C126,INDEX(VendTable!$A$2:$A$109,RANDBETWEEN(1,23))) -> 700018 | E127: 2024-01-02T14:16:06.9086921Z | F127: 8394 | G127: 9818.5215 | H127: 82416669 | I127: 1.220076 | J127: 76862 | K127: 76891213491 | L127: US | M127: 44774.595 | N127: 44776.189 | O127: 44786.784 | P127: 10397261234 | Q127: 982012 | S127: 25612500 | T127: 400
A128: 952000084 | B128: 1 | C128: =IF(A128=A127,PurchaseOrder!C127,INDEX(VendTable!$A$2:$A$109,RANDBETWEEN(1,23))) -> 700017 | E128: 2024-01-02T14:16:06.9086921Z | F128: 38472 | G128: 7671.9345 | H128: 2.9515466e+08 | I128: 1.4640816 | J128: 76870 | K128: 76891213531 | L128: US | M128: 45569.595 | N128: 45571.189 | O128: 45572.784 | P128: 10397261234 | Q128: 981983 | S128: 25612471 | T128: 400
A129: 952000084 | B129: 2 | C129: =IF(A129=A128,PurchaseOrder!C128,INDEX(VendTable!$A$2:$A$109,RANDBETWEEN(1,23))) -> 700017 | E129: 2024-01-02T14:16:06.9086921Z | F129: 41588 | G129: 5678.9303 | H129: 2.3617535e+08 | I129: 1.3022958 | J129: 76857 | K129: 76891213258 | L129: US | M129: 44605.595 | N129: 44609.189 | O129: 44612.784 | P129: 10397261234 | Q129: 982017 | S129: 25612505 | T129: 200
A130: 952000085 | B130: 1 | C130: =IF(A130=A129,PurchaseOrder!C129,INDEX(VendTable!$A$2:$A$109,RANDBETWEEN(1,23))) -> 700006 | E130: 2024-01-02T14:16:06.9086921Z | F130: 23778 | G130: 9568.6503 | H130: 2.2752337e+08 | I130: 1.7953566 | J130: 76861 | K130: 76891213548 | L130: US | M130: 45491.595 | N130: 45493.189 | O130: 45496.784 | P130: 10397261234 | Q130: 982014 | S130: 25612502 | T130: 500
A131: 952000087 | B131: 1 | C131: =IF(A131=A130,PurchaseOrder!C130,INDEX(VendTable!$A$2:$A$109,RANDBETWEEN(1,23))) -> 700021 | E131: 2024-01-02T14:16:06.9086921Z | F131: 45620 | G131: 2742.8844 | H131: 1.2513039e+08 | I131: 1.7942564 | J131: 76861 | K131: 76891213522 | L131: US | M131: 45521.595 | N131: 45523.189 | O131: 45531.784 | P131: 10397261225 | Q131: 981845 | S131: 25612333 | T131: 300
A132: 952000087 | B132: 2 | C132: =IF(A132=A131,PurchaseOrder!C131,INDEX(VendTable!$A$2:$A$109,RANDBETWEEN(1,23))) -> 700021 | E132: 2024-01-02T14:16:06.9086921Z | F132: 22929 | G132: 175.54473 | H132: 4025065.2 | I132: 1.9305963 | J132: 76856 | K132: 76891213300 | L132: US | M132: 45590.595 | N132: 45593.189 | O132: 45600.784 | P132: 10397261234 | Q132: 981928 | S132: 25612416 | T132: 100
A133: 952000087 | B133: 3 | C133: =IF(A133=A132,PurchaseOrder!C132,INDEX(VendTable!$A$2:$A$109,RANDBETWEEN(1,23))) -> 700021 | E133: 2024-01-02T14:16:06.9086921Z | F133: 16765 | G133: 8555.7858 | H133: 1.4343775e+08 | I133: 1.3135378 | J133: 76855 | K133: 76891213149 | L133: US | M133: 45408.595 | N133: 45411.189 | O133: 45416.784 | P133: 10397261234 | Q133: 982015 | S133: 25612503 | T133: 400
A134: 952000087 | B134: 4 | C134: =IF(A134=A133,PurchaseOrder!C133,INDEX(VendTable!$A$2:$A$109,RANDBETWEEN(1,23))) -> 700021 | E134: 2024-01-02T14:16:06.9086921Z | F134: 8996 | G134: 9845.6527 | H134: 88571491 | I134: 1.4251957 | J134: 76854 | K134: 76891213389 | L134: US | M134: 45202.595 | N134: 45205.189 | O134: 45215.784 | P134: 10397261234 | Q134: 982022 | S134: 25612510 | T134: 700
A135: 952000089 | B135: 1 | C135: =IF(A135=A134,PurchaseOrder!C134,INDEX(VendTable!$A$2:$A$109,RANDBETWEEN(1,23))) -> 700001 | E135: 2024-01-02T14:16:06.9086921Z | F135: 18460 | G135: 863.00751 | H135: 15931119 | I135: 1.0946828 | J135: 76862 | K135: 76891213314 | L135: US | M135: 45002.595 | N135: 45004.189 | O135: 45009.784 | P135: 10397261234 | Q135: 981986 | S135: 25612474 | T135: 300
A136: 952000091 | B136: 1 | C136: =IF(A136=A135,PurchaseOrder!C135,INDEX(VendTable!$A$2:$A$109,RANDBETWEEN(1,23))) -> 700003 | E136: 2024-01-02T14:16:06.9086921Z | F136: 5166 | G136: 6835.7316 | H136: 35313389 | I136: 1.8459188 | J136: 76871 | K136: 76891213570 | L136: US | M136: 45250.595 | N136: 45251.189 | O136: 45254.784 | P136: 10397261234 | Q136: 981874 | S136: 25612362 | T136: 100
A137: 952000091 | B137: 2 | C137: =IF(A137=A136,PurchaseOrder!C136,INDEX(VendTable!$A$2:$A$109,RANDBETWEEN(1,23))) -> 700003 | E137: 2024-01-02T14:16:06.9086921Z | F137: 11330 | G137: 8766.2439 | H137: 99321543 | I137: 1.388555 | J137: 76858 | K137: 76891213608 | L137: US | M137: 45401.595 | N137: 45403.189 | O137: 45409.784 | P137: 10397261234 | Q137: 981942 | S137: 25612430 | T137: 300
...

Sheet PurchItem
A1: ItemId | B1: Txt | C1: LastProcessedChange_DateTime | D1: DataLakeModified_DateTime | E1: ValidFrom | F1: ValidTo | G1: IsActive | H1: Price | I1: RecordId | J1: CategoryID
A2: 76891213142 | B2: =INDEX($R$4:$R$609,RANDBETWEEN(1,606))&"-"&INDEX($S$4:$S$10,RANDBETWEEN(1,7)) -> Lock Nut 3-3T | D2: 2024-01-02T14:16:06.9086921Z | E2: 2010-01-01T14:16:06.9086921Z | G2: 1 | H2: =RANDBETWEEN(100,10000)+RAND() -> 5034.8662 | I2: 34521256 | J2: =INDEX($O$3:$O$12,RANDBETWEEN(1,10)) -> 400
A3: 76891213143 | B3: =INDEX($R$4:$R$609,RANDBETWEEN(1,606))&"-"&INDEX($S$4:$S$10,RANDBETWEEN(1,7)) -> Lock Nut 6-8S | D3: 2024-01-02T14:16:06.9086921Z | E3: 2010-01-01T14:16:06.9086921Z | G3: 1 | H3: =RANDBETWEEN(100,10000)+RAND() -> 2099.5083 | I3: 34521257 | J3: =INDEX($O$3:$O$12,RANDBETWEEN(1,10)) -> 600 | O3: 100
A4: 76891213144 | B4: =INDEX($R$4:$R$609,RANDBETWEEN(1,606))&"-"&INDEX($S$4:$S$10,RANDBETWEEN(1,7)) -> Mountain-400-W Silver, 38-8S | D4: 2024-01-02T14:16:06.9086921Z | E4: 2010-01-01T14:16:06.9086921Z | G4: 1 | H4: =RANDBETWEEN(100,10000)+RAND() -> 4043.8015 | I4: 34521258 | J4: =INDEX($O$3:$O$12,RANDBETWEEN(1,10)) -> 700 | O4: 200 | R4: Adjustable Race | S4: 1T
A5: 76891213145 | B5: =INDEX($R$4:$R$609,RANDBETWEEN(1,606))&"-"&INDEX($S$4:$S$10,RANDBETWEEN(1,7)) -> Guide Pulley-6S | D5: 2024-01-02T14:16:06.9086921Z | E5: 2010-01-01T14:16:06.9086921Z | G5: 1 | H5: =RANDBETWEEN(100,10000)+RAND() -> 9273.3062 | I5: 34521259 | J5: =INDEX($O$3:$O$12,RANDBETWEEN(1,10)) -> 700 | O5: 300 | R5: Bearing Ball | S5: 2T
A6: 76891213146 | B6: =INDEX($R$4:$R$609,RANDBETWEEN(1,606))&"-"&INDEX($S$4:$S$10,RANDBETWEEN(1,7)) -> Mountain-500 Silver, 52-8S | D6: 2024-01-02T14:16:06.9086921Z | E6: 2010-01-01T14:16:06.9086921Z | G6: 1 | H6: =RANDBETWEEN(100,10000)+RAND() -> 5461.8261 | I6: 34521260 | J6: =INDEX($O$3:$O$12,RANDBETWEEN(1,10)) -> 600 | O6: 400 | R6: BB Ball Bearing | S6: 3T
A7: 76891213147 | B7: =INDEX($R$4:$R$609,RANDBETWEEN(1,606))&"-"&INDEX($S$4:$S$10,RANDBETWEEN(1,7)) -> HL Crankarm-9Z | D7: 2024-01-02T14:16:06.9086921Z | E7: 2010-01-01T14:16:06.9086921Z | G7: 1 | H7: =RANDBETWEEN(100,10000)+RAND() -> 2264.3354 | I7: 34521261 | J7: =INDEX($O$3:$O$12,RANDBETWEEN(1,10)) -> 300 | O7: 500 | R7: Headset Ball Bearings | S7: 6S
A8: 76891213148 | B8: =INDEX($R$4:$R$609,RANDBETWEEN(1,606))&"-"&INDEX($S$4:$S$10,RANDBETWEEN(1,7)) -> Road-650 Red, 48-3T | D8: 2024-01-02T14:16:06.9086921Z | E8: 2010-01-01T14:16:06.9086921Z | G8: 1 | H8: =RANDBETWEEN(100,10000)+RAND() -> 1059.7105 | I8: 34521262 | J8: =INDEX($O$3:$O$12,RANDBETWEEN(1,10)) -> 900 | O8: 600 | R8: Blade | S8: 8S
A9: 76891213149 | B9: =INDEX($R$4:$R$609,RANDBETWEEN(1,606))&"-"&INDEX($S$4:$S$10,RANDBETWEEN(1,7)) -> Road-150 Red, 62-2T | D9: 2024-01-02T14:16:06.9086921Z | E9: 2010-01-01T14:16:06.9086921Z | G9: 1 | H9: =RANDBETWEEN(100,10000)+RAND() -> 1501.6372 | I9: 34521263 | J9: =INDEX($O$3:$O$12,RANDBETWEEN(1,10)) -> 400 | O9: 700 | R9: LL Crankarm | S9: 9Z
A10: 76891213150 | B10: =INDEX($R$4:$R$609,RANDBETWEEN(1,606))&"-"&INDEX($S$4:$S$10,RANDBETWEEN(1,7)) -> Thin-Jam Lock Nut 11-8S | D10: 2024-01-02T14:16:06.9086921Z | E10: 2010-01-01T14:16:06.9086921Z | G10: 1 | H10: =RANDBETWEEN(100,10000)+RAND() -> 4841.3946 | I10: 34521264 | J10: =INDEX($O$3:$O$12,RANDBETWEEN(1,10)) -> 300 | O10: 800 | R10: ML Crankarm | S10: 10Z
A11: 76891213151 | B11: =INDEX($R$4:$R$609,RANDBETWEEN(1,606))&"-"&INDEX($S$4:$S$10,RANDBETWEEN(1,7)) -> HL Road Frame - Red, 62-6S | D11: 2024-01-02T14:16:06.9086921Z | E11: 2010-01-01T14:16:06.9086921Z | G11: 1 | H11: =RANDBETWEEN(100,10000)+RAND() -> 6578.949 | I11: 34521265 | J11: =INDEX($O$3:$O$12,RANDBETWEEN(1,10)) -> 900 | O11: 900 | R11: HL Crankarm
A12: 76891213152 | B12: =INDEX($R$4:$R$609,RANDBETWEEN(1,606))&"-"&INDEX($S$4:$S$10,RANDBETWEEN(1,7)) -> Reflector-8S | D12: 2024-01-02T14:16:06.9086921Z | E12: 2010-01-01T14:16:06.9086921Z | G12: 1 | H12: =RANDBETWEEN(100,10000)+RAND() -> 169.38212 | I12: 34521266 | J12: =INDEX($O$3:$O$12,RANDBETWEEN(1,10)) -> 400 | O12: 1000 | R12: Chainring Bolts
A13: 76891213153 | B13: =INDEX($R$4:$R$609,RANDBETWEEN(1,606))&"-"&INDEX($S$4:$S$10,RANDBETWEEN(1,7)) -> LL Road Frame - Red, 44-3T | D13: 2024-01-02T14:16:06.9086921Z | E13: 2010-01-01T14:16:06.9086921Z | G13: 1 | H13: =RANDBETWEEN(100,10000)+RAND() -> 9849.995 | I13: 34521267 | J13: =INDEX($O$3:$O$12,RANDBETWEEN(1,10)) -> 1000 | R13: Chainring Nut
A14: 76891213154 | B14: =INDEX($R$4:$R$609,RANDBETWEEN(1,606))&"-"&INDEX($S$4:$S$10,RANDBETWEEN(1,7)) -> Lock Nut 13-6S | D14: 2024-01-02T14:16:06.9086921Z | E14: 2010-01-01T14:16:06.9086921Z | G14: 1 | H14: =RANDBETWEEN(100,10000)+RAND() -> 5837.3436 | I14: 34521268 | J14: =INDEX($O$3:$O$12,RANDBETWEEN(1,10)) -> 400 | R14: Chainring
A15: 76891213155 | B15: =INDEX($R$4:$R$609,RANDBETWEEN(1,606))&"-"&INDEX($S$4:$S$10,RANDBETWEEN(1,7)) -> HL Road Front Wheel-3T | D15: 2024-01-02T14:16:06.9086921Z | E15: 2010-01-01T14:16:06.9086921Z | G15: 1 | H15: =RANDBETWEEN(100,10000)+RAND() -> 3627.1919 | I15: 34521269 | J15: =INDEX($O$3:$O$12,RANDBETWEEN(1,10)) -> 200 | R15: Crown Race
A16: 76891213156 | B16: =INDEX($R$4:$R$609,RANDBETWEEN(1,606))&"-"&INDEX($S$4:$S$10,RANDBETWEEN(1,7)) -> ML Mountain Handlebars-2T | D16: 2024-01-02T14:16:06.9086921Z | E16: 2010-01-01T14:16:06.9086921Z | G16: 1 | H16: =RANDBETWEEN(100,10000)+RAND() -> 9558.6946 | I16: 34521270 | J16: =INDEX($O$3:$O$12,RANDBETWEEN(1,10)) -> 700 | R16: Chain Stays
A17: 76891213157 | B17: =INDEX($R$4:$R$609,RANDBETWEEN(1,606))&"-"&INDEX($S$4:$S$10,RANDBETWEEN(1,7)) -> Lock Washer 2-3T | D17: 2024-01-02T14:16:06.9086921Z | E17: 2010-01-01T14:16:06.9086921Z | G17: 1 | H17: =RANDBETWEEN(100,10000)+RAND() -> 8322.4899 | I17: 34521271 | J17: =INDEX($O$3:$O$12,RANDBETWEEN(1,10)) -> 100 | R17: Decal 1
A18: 76891213158 | B18: =INDEX($R$4:$R$609,RANDBETWEEN(1,606))&"-"&INDEX($S$4:$S$10,RANDBETWEEN(1,7)) -> Cone-Shaped Race-3T | D18: 2024-01-02T14:16:06.9086921Z | E18: 2010-01-01T14:16:06.9086921Z | G18: 1 | H18: =RANDBETWEEN(100,10000)+RAND() -> 7429.0949 | I18: 34521272 | J18: =INDEX($O$3:$O$12,RANDBETWEEN(1,10)) -> 600 | R18: Decal 2
A19: 76891213159 | B19: =INDEX($R$4:$R$609,RANDBETWEEN(1,606))&"-"&INDEX($S$4:$S$10,RANDBETWEEN(1,7)) -> HL Road Frame - Red, 56-1T | D19: 2024-01-02T14:16:06.9086921Z | E19: 2010-01-01T14:16:06.9086921Z | G19: 1 | H19: =RANDBETWEEN(100,10000)+RAND() -> 1020.1296 | I19: 34521273 | J19: =INDEX($O$3:$O$12,RANDBETWEEN(1,10)) -> 400 | R19: Down Tube
A20: 76891213160 | B20: =INDEX($R$4:$R$609,RANDBETWEEN(1,606))&"-"&INDEX($S$4:$S$10,RANDBETWEEN(1,7)) -> Lock Washer 12-8S | D20: 2024-01-02T14:16:06.9086921Z | E20: 2010-01-01T14:16:06.9086921Z | G20: 1 | H20: =RANDBETWEEN(100,10000)+RAND() -> 8462.977 | I20: 34521274 | J20: =INDEX($O$3:$O$12,RANDBETWEEN(1,10)) -> 700 | R20: Mountain End Caps
A21: 76891213161 | B21: =INDEX($R$4:$R$609,RANDBETWEEN(1,606))&"-"&INDEX($S$4:$S$10,RANDBETWEEN(1,7)) -> Metal Angle-1T | D21: 2024-01-02T14:16:06.9086921Z | E21: 2010-01-01T14:16:06.9086921Z | G21: 1 | H21: =RANDBETWEEN(100,10000)+RAND() -> 4626.4083 | I21: 34521275 | J21: =INDEX($O$3:$O$12,RANDBETWEEN(1,10)) -> 500 | R21: Road End Caps
A22: 76891213162 | B22: =INDEX($R$4:$R$609,RANDBETWEEN(1,606))&"-"&INDEX($S$4:$S$10,RANDBETWEEN(1,7)) -> Road-650 Red, 60-10Z | D22: 2024-01-02T14:16:06.9086921Z | E22: 2010-01-01T14:16:06.9086921Z | G22: 1 | H22: =RANDBETWEEN(100,10000)+RAND() -> 4691.9231 | I22: 34521276 | J22: =INDEX($O$3:$O$12,RANDBETWEEN(1,10)) -> 600 | R22: Touring End Caps
A23: 76891213163 | B23: =INDEX($R$4:$R$609,RANDBETWEEN(1,606))&"-"&INDEX($S$4:$S$10,RANDBETWEEN(1,7)) -> Paint - Blue-2T | D23: 2024-01-02T14:16:06.9086921Z | E23: 2010-01-01T14:16:06.9086921Z | G23: 1 | H23: =RANDBETWEEN(100,10000)+RAND() -> 8353.8076 | I23: 34521277 | J23: =INDEX($O$3:$O$12,RANDBETWEEN(1,10)) -> 700 | R23: Fork End
A24: 76891213164 | B24: =INDEX($R$4:$R$609,RANDBETWEEN(1,606))&"-"&INDEX($S$4:$S$10,RANDBETWEEN(1,7)) -> HL Mountain Frame - Black, 42-1T | D24: 2024-01-02T14:16:06.9086921Z | E24: 2010-01-01T14:16:06.9086921Z | G24: 1 | H24: =RANDBETWEEN(100,10000)+RAND() -> 7433.816 | I24: 34521278 | J24: =INDEX($O$3:$O$12,RANDBETWEEN(1,10)) -> 100 | R24: Freewheel
... A508: 76891213648 | B508: =INDEX($R$4:$R$609,RANDBETWEEN(1,606))&"-"&INDEX($S$4:$S$10,RANDBETWEEN(1,7)) -> Mountain-200 Black, 42-3T | D508: 2024-01-02T14:16:06.9086921Z | E508: 2010-01-01T14:16:06.9086921Z | G508: 1 | H508: =RANDBETWEEN(100,10000)+RAND() -> 2614.0754 | I508: 34521762 | J508: =INDEX($O$3:$O$12,RANDBETWEEN(1,10)) -> 200 | R508: LL Touring Frame - Blue, 62
R509: LL Touring Frame - Yellow, 44
R510: LL Touring Frame - Yellow, 50
R511: LL Touring Frame - Yellow, 54
R512: LL Touring Frame - Yellow, 58
R513: LL Touring Frame - Blue, 44
R514: ML Mountain Frame-W - Silver, 40
R515: ML Mountain Frame-W - Silver, 42
R516: ML Mountain Frame-W - Silver, 46
R517: Rear Brakes
R518: LL Mountain Seat/Saddle
R519: ML Mountain Seat/Saddle
R520: HL Mountain Seat/Saddle
... R609: Road-750 Black, 52

Sheet PurchCategory
A1: CategoryId | B1: CategoryName | C1: LastProcessedChange_DateTime | D1: DataLakeModified_DateTime | E1: CategoryGroupId | F1: RecordId
A2: 100 | B2: Utilities | D2: 2024-01-02T14:16:06.9086921Z | E2: 1 | F2: 29836432
A3: 200 | B3: Food | D3: 2024-01-02T14:16:06.9086921Z | E3: 2 | F3: 29836433
A4: 300 | B4: Beverages | D4: 2024-01-02T14:16:06.9086921Z | E4: 2 | F4: 29836434
A5: 400 | B5: Meat | D5: 2024-01-02T14:16:06.9086921Z | E5: 2 | F5: 29836435
A6: 500 | B6: Stationary | D6: 2024-01-02T14:16:06.9086921Z | E6: 3 | F6: 29836436
A7: 600 | B7: Kids | D7: 2024-01-02T14:16:06.9086921Z | E7: 4 | F7: 29836437
A8: 700 | B8: Adult | D8: 2024-01-02T14:16:06.9086921Z | E8: 5 | F8: 29836438
A9: 800 | B9: Electronics | D9: 2024-01-02T14:16:06.9086921Z | E9: 6 | F9: 29836439
A10: 900 | B10: Clothing | D10: 2024-01-02T14:16:06.9086921Z | E10: 7 | F10: 29836440
A11: 1000 | B11: Bathing | D11: 2024-01-02T14:16:06.9086921Z | E11: 8 | F11: 29836441

Sheet SilverTables

Sheet dirparty
E1: JoinKey
C2: Tables | D2: parties | E2: PartyId
D3: partyaddress | E3: PartyNumber
C5: ColumnsNeeded | D5: If name is blank, retain the original column name
C7: Table | D7: Column | E7: Logic | F7: Name
C8: parties | D8: PartyId
C9: parties | D9: PartyName
C10: parties | D10: LastProcessedChange_DateTime
C11: parties | D11: DataLakeModified_DateTime | E11: ConvertToCST
C12: parties | D12: PartyAddressCode
C13: parties | D13: EstablishedDate | E13: ConvertToCST
C14: parties | D14: PartyEmailId
C15: parties | D15: PartyContactNumber
C16: parties | D16: RecordId | F16: PartyRecordId
C17: parties | D17: TaxId
C18: partyaddress | D18: Address
C19: partyaddress | D19: City
C20: partyaddress | D20: State
C21: partyaddress | D21: Country
C22: partyaddress | D22: ZipCode
C23: partyaddress | D23: Region
C24: partyaddress | D24: ValidFrom | E24: ConvertToCST
C25: partyaddress | D25: ValidTo | E25: ConvertToCST
C26: partyaddress | D26: RecordId | F26: PartyAddressRecordId

Sheet dirvendor
C2: Tables | D2: VendTable
C5: ColumnsNeeded | D5: If name is blank, retain the original column name
C7: Table | D7: Column | E7: Logic | F7: Name | G7: Comments
C8: VendTable | D8: VendId | F8: VendorId
C9: VendTable | D9: VendorName
C10: VendTable | D10: LastProcessedChange_DateTime
C11: VendTable | D11: DataLakeModified_DateTime | E11: ConvertToCST
C12: VendTable | D12: Address
C13: VendTable | D13: City
C14: VendTable | D14: State
C15: VendTable | D15: Country
C16: VendTable | D16: ZipCode
C17: VendTable | D17: Region
C18: VendTable | D18: ValidFrom | E18: ConvertToCST
C19: VendTable | D19: ValidTo | E19: ConvertToCST
C20: VendTable | D20: Active
C21: VendTable | D21: RecordId | F21: VendorRecordId
C22: VendTable | D22: TaxId
C23: VendTable | D23: CurrencyCode
C24: VendTable | D24: VendorDiscount | E24: See Comments | G24: If the vendor is based in US, the discount should be 1%, if in UK, the discount should be 0.6% and 0 for rest

Sheet dirpurchcategory
C2: Tables | D2: PurchCategory
C5: ColumnsNeeded | D5: If name is blank, retain the original column name
C7: Table | D7: Column | E7: Logic | F7: Name
C8: PurchCategory | D8: CategoryId
C9: PurchCategory | D9: CategoryName
C10: PurchCategory | D10: LastProcessedChange_DateTime
C11: PurchCategory | D11: DataLakeModified_DateTime | E11: ConvertToCST
C12: PurchCategory | D12: CategoryGroupId
C13: PurchCategory | D13: RecordId | F13: PurchCategoryRecordId

Sheet dirpurchitem
C2: Tables | D2: PurchItem
C5: ColumnsNeeded | D5: If name is blank, retain the original column name
C7: Table | D7: Column | E7: Logic | F7: Name
C8: PurchItem | D8: ItemId
C9: PurchItem | D9: Txt | F9: ProductName
C10: PurchItem | D10: LastProcessedChange_DateTime
C11: PurchItem | D11: DataLakeModified_DateTime | E11: ConvertToCST
C12: PurchItem | D12: ValidFrom | E12: ConvertToCST
C13: PurchItem | D13: ValidTo | E13: ConvertToCST
C14: PurchItem | D14: Price | F14: ProductPerUnitCost
C15: PurchItem | D15: RecordId | F15: PurchItemRecordId
C16: PurchItem | D16: CategoryID

Sheet dircostcenter
C2: Tables | D2: CostCenter
C5: ColumnsNeeded | D5: If name is blank, retain the original column name
C7: Table | D7: Column | E7: Logic | F7: Name
C8: CostCenter | D8: CostCenterNumber
C9: CostCenter | D9: LastProcessedChange_DateTime
C10: CostCenter | D10: DataLakeModified_DateTime | E10: ConvertToCST
C11: CostCenter | D11: Vat
C12: CostCenter | D12: RecordId | F12: CostCenterRecordId

Sheet costcenter
A1: CostCenterNumber | B1: LastProcessedChange_DateTime | C1: DataLakeModified_DateTime | D1: Vat
A2: 76852 | C2: 2024-01-02T14:16:06.9086921Z | D2: =RANDBETWEEN(4,6.5)/100 -> 0.06
A3: 76853 | C3: 2024-01-02T14:16:06.9086921Z | D3: =RANDBETWEEN(4,6.5)/100 -> 0.05
A4: 76854 | C4: 2024-01-02T14:16:06.9086921Z | D4: =RANDBETWEEN(4,6.5)/100 -> 0.04
A5: 76855 | C5: 2024-01-02T14:16:06.9086921Z | D5: =RANDBETWEEN(4,6.5)/100 -> 0.06
A6: 76856 | C6: 2024-01-02T14:16:06.9086921Z | D6: =RANDBETWEEN(4,6.5)/100 -> 0.05
A7: 76857 | C7: 2024-01-02T14:16:06.9086921Z | D7: =RANDBETWEEN(4,6.5)/100 -> 0.06
A8: 76858 | C8: 2024-01-02T14:16:06.9086921Z | D8: =RANDBETWEEN(4,6.5)/100 -> 0.05
A9: 76859 | C9: 2024-01-02T14:16:06.9086921Z | D9: =RANDBETWEEN(4,6.5)/100 -> 0.05
A10: 76860 | C10: 2024-01-02T14:16:06.9086921Z | D10: =RANDBETWEEN(4,6.5)/100 -> 0.04
A11: 76861 | C11: 2024-01-02T14:16:06.9086921Z | D11: =RANDBETWEEN(4,6.5)/100 -> 0.06
A12: 76862 | C12: 2024-01-02T14:16:06.9086921Z | D12: =RANDBETWEEN(4,6.5)/100 -> 0.04
A13: 76863 | C13: 2024-01-02T14:16:06.9086921Z | D13: =RANDBETWEEN(4,6.5)/100 -> 0.04
... A24: 76874 | C24: 2024-01-02T14:16:06.9086921Z | D24: =RANDBETWEEN(4,6.5)/100 -> 0.06

Sheet factpurchaseorder
C1: Table | D1: JoinKey | E1: Table | F1: JoinKey
C3: PurchaseOrder | D3: CostCenter | E3: dimcostcenter | F3: CostCenterNumber
C4: PurchaseOrder | D4: Itemkey | E4: dimpurchitem | F4: ItemId
C5: PurchaseOrder | D5: currencycode | E5: dimcurrency | F5: CurrencyCode
C8: ColumnsNeeded | D8: If name is blank, retain the original column name
C10: Table | D10: Column | E10: Logic | F10: Name | G10: Comments
C11: PurchaseOrder | D11: PoNumber
C12: PurchaseOrder | D12: LineItem
C13: PurchaseOrder | D13: VendId | F13: VendorKey
C14: PurchaseOrder | D14: LastProcessedChange_DateTime
C15: PurchaseOrder | D15: DataLakeModified_DateTime | E15: ConvertToCST
C16: PurchaseOrder | D16: Qty
C17: PurchaseOrder | D17: PurchasePrice
C18: PurchaseOrder | D18: TotalOrder
C19: PurchaseOrder | D19: CostCenter | F19: CostCenterKey
C20: CostCenter | D20: Vat | F20: VatAmount
D21: TotalAmount | E21: TotalOrder + (TotalOrder * Vat) | F21: TotalAmount | G21: Round to 4 digits
C22: PurchaseOrder | D22: ExchangeRate
C23: PurchaseOrder | D23: Itemkey
C24: dimcurrency | D24: CurrencyId | F24: CurrencyKey
C25: PurchaseOrder | D25: OrderDate | E25: ConvertToCST
C26: PurchaseOrder | D26: ShipDate | E26: ConvertToCST
C27: PurchaseOrder | D27: DeliveredDate | E27: ConvertToCST
C28: PurchaseOrder | D28: OrderDate | E28: Cast to int | F28: OrderDateKey
C29: PurchaseOrder | D29: ShipDate | E29: Cast to int | F29: ShipDateKey
C30: PurchaseOrder | D30: DeliveredDate | E30: Cast to int | F30: DeliveredDateKey
C31: PurchaseOrder | D31: TrackingNumber
C32: PurchaseOrder | D32: Batchid | F32: BatchId
C33: PurchaseOrder | D33: CreatedBy
C34: PurchaseOrder | D34: RecordId | F34: PurchaseOrderRecordId
C35: PurchaseOrder | D35: CategoryID | F35: CategoryKey

Sheet Sales

Sheet SalesOrderLine
A1: SalesOrderNumber | B1: LastProcessedChange_DateTime | C1: DataLakeModified_DateTime | D1: SalesOrderLine | E1: ItemId | F1: Qty | G1: Price | H1: VatPercentage | I1: CurrencyCode | J1: BookDate | K1: ShippedDate | L1: DeliveredDate | M1: TrackingNumber | N1: CustId | O1: PaymentTypeDesc | P1: RecordId
A2: 93827211982 | C2: 2024-01-02T14:16:06.9086921Z | D2: 1 | E2: 76891213323 | F2: =RANDBETWEEN(1,100) -> 65 | G2: =VLOOKUP(E2,PurchItem!$A$2:$H$508,8,0) -> 2479.1592 | H2: 0.04 | I2: USD | J2: 44601.595 | K2: 44602.189 | L2: 44608.784 | M2: 10029727212 | N2: 11000 | O2: CreditCard | P2: 52936136
A3: 93827211982 | C3: 2024-01-02T14:16:06.9086921Z | D3: 2 | E3: 76891213151 | F3: =RANDBETWEEN(1,100) -> 79 | G3: =VLOOKUP(E3,PurchItem!$A$2:$H$508,8,0) -> 6578.949 | H3: 0.05 | I3: USD | J3: 44933.595 | K3: 44935.189 | L3: 44942.784 | M3: =IF(A3<>A2,M2+1,M2) -> 10029727212 | N3: =IF(M3<>M2,INDEX(CustInfo!$A$2:$A$1001,RANDBETWEEN(1,1000)),N2) -> 11000 | O3: CreditCard | P3: 52936137
A4: 93827211982 | C4: 2024-01-02T14:16:06.9086921Z | D4: 3 | E4: 76891213394 | F4: =RANDBETWEEN(1,100) -> 52 | G4: =VLOOKUP(E4,PurchItem!$A$2:$H$508,8,0) -> 4295.2255 | H4: 0.04 | I4: USD | J4: 45524.595 | K4: 45525.189 | L4: 45527.784 | M4: =IF(A4<>A3,M3+1,M3) -> 10029727212 | N4: =IF(M4<>M3,INDEX(CustInfo!$A$2:$A$1001,RANDBETWEEN(1,1000)),N3) -> 11000 | O4: CreditCard | P4: 52936138
A5: 93827211982 | C5: 2024-01-02T14:16:06.9086921Z | D5: 4 | E5: 76891213290 | F5: =RANDBETWEEN(1,100) -> 84 | G5: =VLOOKUP(E5,PurchItem!$A$2:$H$508,8,0) -> 8789.9228 | H5: 0.05 | I5: USD | J5: 45282.595 | K5: 45283.189 | L5: 45293.784 | M5: =IF(A5<>A4,M4+1,M4) -> 10029727212 | N5: =IF(M5<>M4,INDEX(CustInfo!$A$2:$A$1001,RANDBETWEEN(1,1000)),N4) -> 11000 | O5: CreditCard | P5: 52936139
A6: 93827211983 | C6: 2024-01-02T14:16:06.9086921Z | D6: 1 | E6: 76891213486 | F6: =RANDBETWEEN(1,100) -> 21 | G6: =VLOOKUP(E6,PurchItem!$A$2:$H$508,8,0) -> 9918.4804 | H6: 0.05 | I6: USD | J6: 44715.595 | K6: 44719.189 | L6: 44727.784 | M6: =IF(A6<>A5,M5+1,M5) -> 10029727213 | N6: =IF(M6<>M5,INDEX(CustInfo!$A$2:$A$1001,RANDBETWEEN(1,1000)),N5) -> 11984 | O6: CashOnDelivery | P6: 52936140
A7: 93827211983 | C7: 2024-01-02T14:16:06.9086921Z | D7: 2 | E7: 76891213442 | F7: =RANDBETWEEN(1,100) -> 35 | G7: =VLOOKUP(E7,PurchItem!$A$2:$H$508,8,0) -> 3996.4553 | H7: 0.04 | I7: USD | J7: 44983.595 | K7: 44986.189 | L7: 44986.784 | M7: =IF(A7<>A6,M6+1,M6) -> 10029727213 | N7: =IF(M7<>M6,INDEX(CustInfo!$A$2:$A$1001,RANDBETWEEN(1,1000)),N6) -> 11984 | O7: CashOnDelivery | P7: 52936141
A8: 93827211983 | C8: 2024-01-02T14:16:06.9086921Z | D8: 3 | E8: 76891213468 | F8: =RANDBETWEEN(1,100) -> 18 | G8: =VLOOKUP(E8,PurchItem!$A$2:$H$508,8,0) -> 8720.5574 | H8: 0.06 | I8: USD | J8: 45193.595 | K8: 45195.189 | L8: 45205.784 | M8: =IF(A8<>A7,M7+1,M7) -> 10029727213 | N8: =IF(M8<>M7,INDEX(CustInfo!$A$2:$A$1001,RANDBETWEEN(1,1000)),N7) -> 11984 | O8: CashOnDelivery | P8: 52936142
A9: 93827211984 | C9: 2024-01-02T14:16:06.9086921Z | D9: 1 | E9: 76891213526 | F9: =RANDBETWEEN(1,100) -> 17 | G9: =VLOOKUP(E9,PurchItem!$A$2:$H$508,8,0) -> 8212.805 | H9: 0.04 | I9: USD | J9: 44916.595 | K9: 44920.189 | L9: 44927.784 | M9: =IF(A9<>A8,M8+1,M8) -> 10029727214 | N9: =IF(M9<>M8,INDEX(CustInfo!$A$2:$A$1001,RANDBETWEEN(1,1000)),N8) -> 11240 | O9: DebitCard | P9: 52936143
A10: 93827211984 | C10: 2024-01-02T14:16:06.9086921Z | D10: 2 | E10: 76891213249 | F10: =RANDBETWEEN(1,100) -> 50 | G10: =VLOOKUP(E10,PurchItem!$A$2:$H$508,8,0) -> 8086.2833 | H10: 0.04 | I10: USD | J10: 44860.595 | K10: 44863.189 | L10: 44863.784 | M10: =IF(A10<>A9,M9+1,M9) -> 10029727214 | N10: =IF(M10<>M9,INDEX(CustInfo!$A$2:$A$1001,RANDBETWEEN(1,1000)),N9) -> 11240 | O10: DebitCard | P10: 52936144
A11: 93827211985 | C11: 2024-01-02T14:16:06.9086921Z | D11: 1 | E11: 76891213362 | F11: =RANDBETWEEN(1,100) -> 59 | G11: =VLOOKUP(E11,PurchItem!$A$2:$H$508,8,0) -> 2524.8525 | H11: 0.06 | I11: USD | J11: 45302.595 | K11: 45304.189 | L11: 45313.784 | M11: =IF(A11<>A10,M10+1,M10) -> 10029727215 | N11: =IF(M11<>M10,INDEX(CustInfo!$A$2:$A$1001,RANDBETWEEN(1,1000)),N10) -> 11873 | O11: DebitCard | P11: 52936145
A12: 93827211986 | C12: 2024-01-02T14:16:06.9086921Z | D12: 1 | E12: 76891213284 | F12: =RANDBETWEEN(1,100) -> 38 | G12: =VLOOKUP(E12,PurchItem!$A$2:$H$508,8,0) -> 8438.9293 | H12: 0.06 | I12: USD | J12: 44900.595 | K12: 44903.189 | L12: 44906.784 | M12: =IF(A12<>A11,M11+1,M11) -> 10029727216 | N12: =IF(M12<>M11,INDEX(CustInfo!$A$2:$A$1001,RANDBETWEEN(1,1000)),N11) -> 11619 | O12: DebitCard | P12: 52936146
A13: 93827211987 | C13: 2024-01-02T14:16:06.9086921Z | D13: 1 | E13: 76891213184 | F13: =RANDBETWEEN(1,100) -> 48 | G13: =VLOOKUP(E13,PurchItem!$A$2:$H$508,8,0) -> 5805.119 | H13: 0.05 | I13: USD | J13: 44643.595 | K13: 44646.189 | L13: 44655.784 | M13: =IF(A13<>A12,M12+1,M12) -> 10029727217 | N13: =IF(M13<>M12,INDEX(CustInfo!$A$2:$A$1001,RANDBETWEEN(1,1000)),N12) -> 11969 | O13: CreditCard | P13: 52936147
A14: 93827211987 | C14: 2024-01-02T14:16:06.9086921Z | D14: 2 | E14: 76891213555 | F14: =RANDBETWEEN(1,100) -> 84 | G14: =VLOOKUP(E14,PurchItem!$A$2:$H$508,8,0) -> 6639.1318 | H14: 0.04 | I14: USD | J14: 45037.595 | K14: 45041.189 | L14: 45049.784 | M14: =IF(A14<>A13,M13+1,M13) -> 10029727217 | N14: =IF(M14<>M13,INDEX(CustInfo!$A$2:$A$1001,RANDBETWEEN(1,1000)),N13) -> 11969 | O14: CreditCard | P14: 52936148
... A125: 93827212028 | C125: 2024-01-02T14:16:06.9086921Z | D125: 2 | E125: 76891213371 | F125: =RANDBETWEEN(1,100) -> 98 | G125: =VLOOKUP(E125,PurchItem!$A$2:$H$508,8,0) -> 2898.9854 | H125: 0.06 | I125: USD | J125: 45409.595 | K125: 45412.189 | L125: 45417.784 | M125: =IF(A125<>A124,M124+1,M124) -> 10029727258 | N125: =IF(M125<>M124,INDEX(CustInfo!$A$2:$A$1001,RANDBETWEEN(1,1000)),N124) -> 11863 | O125: DebitCard | P125: 52936259
A126: 93827212028 | C126: 2024-01-02T14:16:06.9086921Z | D126: 3 | E126: 76891213551 | F126: =RANDBETWEEN(1,100) -> 53 | G126: =VLOOKUP(E126,PurchItem!$A$2:$H$508,8,0) -> 8257.6439 | H126: 0.06 | I126: USD | J126: =RANDBETWEEN(DATE(2022,1,1),TODAY()-30)+$U$2 -> 45468 | K126: =J126+RANDBETWEEN(0,3)+$U$2 -> 45468 | L126: =K126+RANDBETWEEN(0,10)+$U$2 -> 45468 | M126: =IF(A126<>A125,M125+1,M125) -> 10029727258 | N126: =IF(M126<>M125,INDEX(CustInfo!$A$2:$A$1001,RANDBETWEEN(1,1000)),N125) -> 11863 | O126: DebitCard | P126: 52936260
A127: 93827212028 | C127: 2024-01-02T14:16:06.9086921Z | D127: 4 | E127: 76891213336 | F127: =RANDBETWEEN(1,100) -> 11 | G127: =VLOOKUP(E127,PurchItem!$A$2:$H$508,8,0) -> 2324.4801 | H127: 0.04 | I127: USD | J127: 44774.595 | K127: 44776.189 | L127: 44786.784 | M127: =IF(A127<>A126,M126+1,M126) -> 10029727258 | N127: =IF(M127<>M126,INDEX(CustInfo!$A$2:$A$1001,RANDBETWEEN(1,1000)),N126) -> 11863 | O127: DebitCard | P127: 52936261
A128: 93827212029 | C128: 2024-01-02T14:16:06.9086921Z | D128: 1 | E128: 76891213251 | F128: =RANDBETWEEN(1,100) -> 21 | G128: =VLOOKUP(E128,PurchItem!$A$2:$H$508,8,0) -> 1404.0728 | H128: 0.04 | I128: USD | J128: 45569.595 | K128: 45571.189 | L128: 45572.784 | M128: =IF(A128<>A127,M127+1,M127) -> 10029727259 | N128: =IF(M128<>M127,INDEX(CustInfo!$A$2:$A$1001,RANDBETWEEN(1,1000)),N127) -> 11873 | O128: DebitCard | P128: 52936262
A129: 93827212029 | C129: 2024-01-02T14:16:06.9086921Z | D129: 2 | E129: 76891213601 | F129: =RANDBETWEEN(1,100) -> 58 | G129: =VLOOKUP(E129,PurchItem!$A$2:$H$508,8,0) -> 3260.9614 | H129: 0.04 | I129: USD | J129: 44605.595 | K129: 44609.189 | L129: 44612.784 | M129: =IF(A129<>A128,M128+1,M128) -> 10029727259 | N129: =IF(M129<>M128,INDEX(CustInfo!$A$2:$A$1001,RANDBETWEEN(1,1000)),N128) -> 11873 | O129: DebitCard | P129: 52936263
A130: 93827212029 | C130: 2024-01-02T14:16:06.9086921Z | D130: 3 | E130: 76891213592 | F130: =RANDBETWEEN(1,100) -> 37 | G130: =VLOOKUP(E130,PurchItem!$A$2:$H$508,8,0) -> 4470.4136 | H130: 0.04 | I130: USD | J130: 45491.595 | K130: 45493.189 | L130: 45496.784 | M130: =IF(A130<>A129,M129+1,M129) -> 10029727259 | N130: =IF(M130<>M129,INDEX(CustInfo!$A$2:$A$1001,RANDBETWEEN(1,1000)),N129) -> 11873 | O130: DebitCard | P130: 52936264
A131: 93827212030 | C131: 2024-01-02T14:16:06.9086921Z | D131: 1 | E131: 76891213609 | F131: =RANDBETWEEN(1,100) -> 47 | G131: =VLOOKUP(E131,PurchItem!$A$2:$H$508,8,0) -> 9297.0289 | H131: 0.04 | I131: USD | J131: 45521.595 | K131: 45523.189 | L131: 45531.784 | M131: =IF(A131<>A130,M130+1,M130) -> 10029727260 | N131: =IF(M131<>M130,INDEX(CustInfo!$A$2:$A$1001,RANDBETWEEN(1,1000)),N130) -> 11792 | O131: DebitCard | P131: 52936265
A132: 93827212031 | C132: 2024-01-02T14:16:06.9086921Z | D132: 1 | E132: 76891213277 | F132: =RANDBETWEEN(1,100) -> 57 | G132: =VLOOKUP(E132,PurchItem!$A$2:$H$508,8,0) -> 424.15139 | H132: 0.06 | I132: USD | J132: 45590.595 | K132: 45593.189 | L132: 45600.784 | M132: =IF(A132<>A131,M131+1,M131) -> 10029727261 | N132: =IF(M132<>M131,INDEX(CustInfo!$A$2:$A$1001,RANDBETWEEN(1,1000)),N131) -> 11830 | O132: CashOnDelivery | P132: 52936266
A133: 93827212031 | C133: 2024-01-02T14:16:06.9086921Z | D133: 2 | E133: 76891213273 | F133: =RANDBETWEEN(1,100) -> 71 | G133: =VLOOKUP(E133,PurchItem!$A$2:$H$508,8,0) -> 3906.591 | H133: 0.06 | I133: USD | J133: 45408.595 | K133: 45411.189 | L133: 45416.784 | M133: =IF(A133<>A132,M132+1,M132) -> 10029727261 | N133: =IF(M133<>M132,INDEX(CustInfo!$A$2:$A$1001,RANDBETWEEN(1,1000)),N132) -> 11830 | O133: CashOnDelivery | P133: 52936267
A134: 93827212032 | C134: 2024-01-02T14:16:06.9086921Z | D134: 1 | E134: 76891213220 | F134: =RANDBETWEEN(1,100) -> 98 | G134: =VLOOKUP(E134,PurchItem!$A$2:$H$508,8,0) -> 2008.1764 | H134: 0.05 | I134: USD | J134: 45202.595 | K134: 45205.189 | L134: 45215.784 | M134: =IF(A134<>A133,M133+1,M133) -> 10029727262 | N134: =IF(M134<>M133,INDEX(CustInfo!$A$2:$A$1001,RANDBETWEEN(1,1000)),N133) -> 11680 | O134: DebitCard | P134: 52936268
A135: 93827212032 | C135: 2024-01-02T14:16:06.9086921Z | D135: 2 | E135: 76891213360 | F135: =RANDBETWEEN(1,100) -> 51 | G135: =VLOOKUP(E135,PurchItem!$A$2:$H$508,8,0) -> 6087.4433 | H135: 0.04 | I135: USD | J135: 45002.595 | K135: 45004.189 | L135: 45009.784 | M135: =IF(A135<>A134,M134+1,M134) -> 10029727262 | N135: =IF(M135<>M134,INDEX(CustInfo!$A$2:$A$1001,RANDBETWEEN(1,1000)),N134) -> 11680 | O135: DebitCard | P135: 52936269
A136: 93827212032 | C136: 2024-01-02T14:16:06.9086921Z | D136: 3 | E136: 76891213571 | F136: =RANDBETWEEN(1,100) -> 25 | G136: =VLOOKUP(E136,PurchItem!$A$2:$H$508,8,0) -> 3575.5287 | H136: 0.06 | I136: USD | J136: 45250.595 | K136: 45251.189 | L136: 45254.784 | M136: =IF(A136<>A135,M135+1,M135) -> 10029727262 | N136: =IF(M136<>M135,INDEX(CustInfo!$A$2:$A$1001,RANDBETWEEN(1,1000)),N135) -> 11680 | O136: DebitCard | P136: 52936270
A137: 93827212032 | C137: 2024-01-02T14:16:06.9086921Z | D137: 4 | E137: 76891213601 | F137: =RANDBETWEEN(1,100) -> 62 | G137: =VLOOKUP(E137,PurchItem!$A$2:$H$508,8,0) -> 3260.9614 | H137: 0.05 | I137: USD | J137: 45401.595 | K137: 45403.189 | L137: 45409.784 | M137: =IF(A137<>A136,M136+1,M136) -> 10029727262 | N137: =IF(M137<>M136,INDEX(CustInfo!$A$2:$A$1001,RANDBETWEEN(1,1000)),N136) -> 11680 | O137: DebitCard | P137: 52936271
A138: 93827212033 | C138: 2024-01-02T14:16:06.9086921Z | D138: 1 | E138: 76891213334 | F138: =RANDBETWEEN(1,100) -> 26 | G138: =VLOOKUP(E138,PurchItem!$A$2:$H$508,8,0) -> 8701.4874 | H138: 0.04 | I138: USD | J138: 45421.595 | K138: 45422.189 | L138: 45432.784 | M138: =IF(A138<>A137,M137+1,M137) -> 10029727263 | N138: =IF(M138<>M137,INDEX(CustInfo!$A$2:$A$1001,RANDBETWEEN(1,1000)),N137) -> 11338 | O138: CashOnDelivery | P138: 52936272
... A195: 93827212051 | C195: 2024-01-02T14:16:06.9086921Z | D195: 3 | E195: 76891213551 | F195: =RANDBETWEEN(1,100) -> 89 | G195: =VLOOKUP(E195,PurchItem!$A$2:$H$508,8,0) -> 8257.6439 | H195: 0.05 | I195: USD | J195: 44870.595 | K195: 44873.189 | L195: 44883.784 | M195: =IF(A195<>A194,M194+1,M194) -> 10029727281 | N195: =IF(M195<>M194,INDEX(CustInfo!$A$2:$A$1001,RANDBETWEEN(1,1000)),N194) -> 11333 | O195: CreditCard | P195: 52936329
A196: 93827212052 | C196: 2024-01-02T14:16:06.9086921Z | D196: 1 | E196: 76891213492 | F196: =RANDBETWEEN(1,100) -> 23 | G196: =VLOOKUP(E196,PurchItem!$A$2:$H$508,8,0) -> 4212.9527 | H196: 0.06 | I196: USD | J196: 44601.595 | K196: 44602.189 | M196: =IF(A196<>A195,M195+1,M195) -> 10029727282 | N196: =IF(M196<>M195,INDEX(CustInfo!$A$2:$A$1001,RANDBETWEEN(1,1000)),N195) -> 11201 | O196: CashOnDelivery | P196: 52936330
A197: 93827212052 | C197: 2024-01-02T14:16:06.9086921Z | D197: 2 | E197: 76891213169 | F197: =RANDBETWEEN(1,100) -> 16 | G197: =VLOOKUP(E197,PurchItem!$A$2:$H$508,8,0) -> 1750.9223 | H197: 0.04 | I197: USD | J197: 44933.595 | K197: 44935.189 | M197: =IF(A197<>A196,M196+1,M196) -> 10029727282 | N197: =IF(M197<>M196,INDEX(CustInfo!$A$2:$A$1001,RANDBETWEEN(1,1000)),N196) -> 11201 | O197: CashOnDelivery | P197: 52936331
A198: 93827212053 | C198: 2024-01-02T14:16:06.9086921Z | D198: 1 | E198: 76891213578 | F198: =RANDBETWEEN(1,100) -> 52 | G198: =VLOOKUP(E198,PurchItem!$A$2:$H$508,8,0) -> 9231.1247 | H198: 0.06 | I198: USD | J198: 45524.595 | K198: 45525.189 | M198: =IF(A198<>A197,M197+1,M197) -> 10029727283 | N198: =IF(M198<>M197,INDEX(CustInfo!$A$2:$A$1001,RANDBETWEEN(1,1000)),N197) -> 11977 | O198: CashOnDelivery | P198: 52936332
A199: 93827212053 | C199: 2024-01-02T14:16:06.9086921Z | D199: 2 | E199: 76891213245 | F199: =RANDBETWEEN(1,100) -> 1 | G199: =VLOOKUP(E199,PurchItem!$A$2:$H$508,8,0) -> 4529.342 | H199: 0.04 | I199: USD | J199: 45282.595 | K199: 45283.189 | M199: =IF(A199<>A198,M198+1,M198) -> 10029727283 | N199: =IF(M199<>M198,INDEX(CustInfo!$A$2:$A$1001,RANDBETWEEN(1,1000)),N198) -> 11977 | O199: CashOnDelivery | P199: 52936333
A200: 93827212053 | C200: 2024-01-02T14:16:06.9086921Z | D200: 3 | E200: 76891213593 | F200: =RANDBETWEEN(1,100) -> 45 | G200: =VLOOKUP(E200,PurchItem!$A$2:$H$508,8,0) -> 2737.5203 | H200: 0.04 | I200: USD | J200: 44715.595 | K200: 44719.189 | M200: =IF(A200<>A199,M199+1,M199) -> 10029727283 | N200: =IF(M200<>M199,INDEX(CustInfo!$A$2:$A$1001,RANDBETWEEN(1,1000)),N199) -> 11977 | O200: CashOnDelivery | P200: 52936334
A201: 93827212054 | C201: 2024-01-02T14:16:06.9086921Z | D201: 1 | E201: 76891213449 | F201: =RANDBETWEEN(1,100) -> 67 | G201: =VLOOKUP(E201,PurchItem!$A$2:$H$508,8,0) -> 8466.7709 | H201: 0.04 | I201: USD | J201: 44983.595 | K201: 44986.189 | M201: =IF(A201<>A200,M200+1,M200) -> 10029727284 | N201: =IF(M201<>M200,INDEX(CustInfo!$A$2:$A$1001,RANDBETWEEN(1,1000)),N200) -> 11712 | O201: CreditCard | P201: 52936335
A202: 93827212054 | C202: 2024-01-02T14:16:06.9086921Z | D202: 2 | E202: 76891213232 | F202: =RANDBETWEEN(1,100) -> 7 | G202: =VLOOKUP(E202,PurchItem!$A$2:$H$508,8,0) -> 8714.7937 | H202: 0.06 | I202: USD | J202: 45193.595 | K202: 45195.189 | M202: =IF(A202<>A201,M201+1,M201) -> 10029727284 | N202: =IF(M202<>M201,INDEX(CustInfo!$A$2:$A$1001,RANDBETWEEN(1,1000)),N201) -> 11712 | O202: CreditCard | P202: 52936336
A203: 93827212054 | C203: 2024-01-02T14:16:06.9086921Z | D203: 3 | E203: 76891213469 | F203: =RANDBETWEEN(1,100) -> 83 | G203: =VLOOKUP(E203,PurchItem!$A$2:$H$508,8,0) -> 3640.4378 | H203: 0.05 | I203: USD | J203: 44916.595 | K203: 44920.189 | M203: =IF(A203<>A202,M202+1,M202) -> 10029727284 | N203: =IF(M203<>M202,INDEX(CustInfo!$A$2:$A$1001,RANDBETWEEN(1,1000)),N202) -> 11712 | O203: CreditCard | P203: 52936337
A204: 93827212055 | C204: 2024-01-02T14:16:06.9086921Z | D204: 1 | E204: 76891213223 | F204: =RANDBETWEEN(1,100) -> 91 | G204: =VLOOKUP(E204,PurchItem!$A$2:$H$508,8,0) -> 9143.6021 | H204: 0.05 | I204: USD | J204: 44860.595 | K204: 44863.189 | M204: =IF(A204<>A203,M203+1,M203) -> 10029727285 | N204: =IF(M204<>M203,INDEX(CustInfo!$A$2:$A$1001,RANDBETWEEN(1,1000)),N203) -> 11757 | O204: DebitCard | P204: 52936338
A205: 93827212055 | C205: 2024-01-02T14:16:06.9086921Z | D205: 2 | E205: 76891213572 | F205: =RANDBETWEEN(1,100) -> 8 | G205: =VLOOKUP(E205,PurchItem!$A$2:$H$508,8,0) -> 8369.1775 | H205: 0.05 | I205: USD | J205: 45302.595 | K205: 45304.189 | M205: =IF(A205<>A204,M204+1,M204) -> 10029727285 | N205: =IF(M205<>M204,INDEX(CustInfo!$A$2:$A$1001,RANDBETWEEN(1,1000)),N204) -> 11757 | O205: DebitCard | P205: 52936339
A206: 93827212055 | C206: 2024-01-02T14:16:06.9086921Z | D206: 3 | E206: 76891213327 | F206: =RANDBETWEEN(1,100) -> 96 | G206: =VLOOKUP(E206,PurchItem!$A$2:$H$508,8,0) -> 2188.0437 | H206: 0.06 | I206: USD | J206: 44900.595 | K206: 44903.189 | M206: =IF(A206<>A205,M205+1,M205) -> 10029727285 | N206: =IF(M206<>M205,INDEX(CustInfo!$A$2:$A$1001,RANDBETWEEN(1,1000)),N205) -> 11757 | O206: DebitCard | P206: 52936340
...

Sheet factsalesorderline
B1: Table | C1: JoinKey | D1: Table | E1: JoinKey
B3: salesorderline | C3: CurrencyCode | D3: bronze.currency | E3: Code
B4: salesorderline | C4: PaymentTypeDesc | D4: silver.dimpaymenttypes | E4: PaymentTypeDesc
B5: promotable
B8: ColumnsNeeded | C8: If name is blank, retain the original column name
B10: Table | C10: Column | D10: Logic | E10: Name | F10: Comments
B11: salesorderline | C11: SalesOrderNumber
B12: salesorderline | C12: SalesOrderLine
B13: salesorderline | C13: LastProcessedChange_DateTime
B14: salesorderline | C14: DataLakeModified_DateTime | D14: ConvertToCST
B15: salesorderline | C15: ItemId
B16: salesorderline | C16: Qty
B17: salesorderline | C17: Price
C18: TotalAmount | D18: Qty * Price
C19: TotalAmountWithDiscount | F19: Apply the discount as per applicable promotion
B20: salesorderline | C20: VatPercentage
C21: VatAmount | D21: TotalAmountWithDiscount * VatPercentage
C22: TotalOrderAmount | D22: TotalAmountWithDiscount + VatAmount
B23: currency | C23: CurrencyId
B24: salesorderline | C24: BookDate | D24: ConvertToCST
B25: salesorderline | C25: BookDateKey | D25: Convert to Int
B26: salesorderline | C26: ShippedDate | D26: ConvertToCST
B27: salesorderline | C27: ShippedDateKey | D27: Convert to Int
B28: salesorderline | C28: DeliveredDate | D28: ConvertToCST
B29: salesorderline | C29: DeliveredKey | D29: Convert to Int
B30: salesorderline | C30: TrackingNumber
B31: salesorderline | C31: CustId
B32: silver.dimpaymenttypes | C32: PaymentTypeId
B33: promotable | C33: PromotionId
B34: salesorderline | C34: RecordId | E34: SalesOrderLineRecordId

Sheet dimpaymentTypes
A1: Tables | B1: SalesOrderLine
A4: ColumnsNeeded | B4: If name is blank, retain the original column name
A6: Table | B6: Column | C6: Logic | D6: Name | E6: Comments
B7: PaymentTypeId | E7: Generate incremental and sequential ids starting from 1 for each row
A8: SalesOrderLine | B8: PaymentTypeDesc

Sheet CustInfo
A1: CustomerId | B1: LastProcessedChange_DateTime | C1: DataLakeModified_DateTime | D1: CustomerName | E1: Email | F1: Phone | G1: Address | H1: City | I1: State | J1: Country | K1: ZipCode | L1: Region | M1: SignupDate | N1: RecordId
A2: 11000 | C2: 2024-01-02T14:16:06.9086921Z | D2: Jon Yang | E2: jon24@gmail.com | F2: 1 (11) 500 555-0162 | G2: 3761 N. 14th St | J2: United States | N2: 59251632
A3: 11001 | C3: 2024-01-02T14:16:06.9086921Z | D3: Eugene Huang | E3: eugene10@gmail.com | F3: 1 (11) 500 555-0110 | G3: 2243 W St. | J3: United States | N3: 59251633
A4: 11002 | C4: 2024-01-02T14:16:06.9086921Z | D4: Ruben Torres | E4: ruben35@gmail.com | F4: 1 (11) 500 555-0184 | G4: 5844 Linden Land | J4: United States | N4: 59251634
A5: 11003 | C5: 2024-01-02T14:16:06.9086921Z | D5: Christy Zhu | E5: christy12@gmail.com | F5: 1 (11) 500 555-0162 | G5: 1825 Village Pl. | J5: United States | N5: 59251635
